Workbook

Sheet Instrucciones
A1: Cedears | C1: Esta planilla es gratis, igualmente te dejo mi alias por si queres ayudarme a que pueda hacer más contenido como este: luis.dd.mp
C2: Para hacer uso de la planilla, debe seleccionar en el borde izquierdo superior: Archivo - Hacer una copia
C3: Tenga en cuenta que los valores son tomados con fórmulas de información provista por Google Finance - Se actualizan cada 20 minutos
C4: Siga las instrucciones detalladas abajo para un correcto funcionamiento de la planilla. Por favor chequee la información y mire el video antes de consultar dudas
C5: La sección "cartera" no se debe tocar, se completa automáticamente con las fórmulas de "operaciones abiertas"
C6: Redes sociales Finanzas Con Luis: YouTube (FinanzasConLuisDD), Instagram (@FinanzasConLuisDD), TikTok (@FinanzasConLuisDD)
C7: Unite a la comunidad de WhatsApp: https://chat.whatsapp.com/IgPxO6cBCom3ChTJphTGGe
C8: Link al video explicativo de YouTube: https://www.youtube.com/watch?v=vLqp9A7wnqk
B10: Completar: | C10: Ticker: El ticker debe ser el que cotiza en NY. Ejemplo: Disney es DIS, no DISN. Hay muchas acciones en las que es igual, pero en caso de ver un error, puede deberse a esto. Completar en mayúscula.
C11: Broker: Seleccionar aquel en el que se hizo la operación. Esto es útil en caso de operar en más de uno.
C12: Cantidad: Número de CEDEARs comprados
A13: OPERACIONES ABIERTAS | C13: Fecha de compra: El día en que compra
C14: Dólar compra: Dólar CCL en el momento de la compra - Escribir manualmente (NO como fórmula) para evitar su actualización posterior (esto es para fijar el precio de compra). Su referencia está en la celda G2)
C15: Precio de compra: Cantidad de pesos que se pagó por cada CEDEAR
C16: Dividendos: Se debe completar a mano en caso de cobrarlos. Sirve para reflejar el verdadero rendimiento de la inversión. Puede estar vacío o en 0.
C17: Comisión + Imp: Completar las comisiones, derechos de mercado, impuestos, etc. que se pagan, de modo tal que se reflejen correctamente en el precio de compra y en el precio actual
C18: Todos los otros valores se autocompletan. No se deben tocar las otras celdas.
C20: Una vez que se venda una operación abierta en su totalidad, se debe copiar y pegar (solo valores) desde operación abierta hacia operación cerrada.
A21: OPERACIONES CERRADAS | C21: Luego, se debe borrar la línea de operaciones abiertas ya que no se tiene más la posesión de esos activos. Se recomienda borrar contenido y no borrar la fila completa.
C22: En caso que la venta sea parcial (ejemplo: compra de 100 cedears y venta de 60), se debe cambiar en el cálculo de operaciones abiertas (de 100 a 60),
C23: copiar y pegar esos valores (solo valores) y luego cambiar la cantidad en operaciones abiertas (de 60 a 40, que son las cedears que quedan sin vender)
C24: Las operaciones cerradas sirven para llevar registro del pasado. En caso de no querer llevarlo, se puede optar por no completarlo
C26: En caso de un split de acciones, se debe ajustar el precio de compra (columna H). Ejemplo: Split en 10 acciones. Debo poner = Precio de compra / 10
A27: ACLARACIONES | C27: No se puede editar esta misma planilla, debés crearte una copia en tu drive (Archivo - Crear copia). De lo contrario, todos estarían viendo tus inversiones en esta planilla
C28: La parte de dividendos se completa únicamente al cobrarlos y se puede ver en el broker. Es opcional, en caso de no completarlo, se "subestima" el rendimiento
C29: En caso de usar brokers con distintas comisiones, se puede ajustar manualmente la formula de las columnas I, L y Z o directamente colocar la comisión del broker más usado o el de comisiones más altas

Sheet CEDEARs
A1: OPERACIONES ABIERTAS | G1: Dólar CCL | H1: Comisión + Imp | T1: CARTERA
G2: ='Info CEDEARs'!J3 -> 1472.2486 | H2: 0.006
A3: Ticker | B3: Broker | C3: Cantidad | D3: Ratio | E3: Cantidad (Real) | F3: Fecha compra | G3: Dólar compra | H3: Precio compra | I3: Precio (USD) | J3: Valor compra | K3: Fecha actual | L3: Precio actual (USD) | M3: Dividendos (USD) | N3: Valor actual | O3: Días | P3: Variación (%) | Q3: Variación ($) | R3: Proporción | T3: Ticker | U3: Cantidad | V3: Ratio | W3: Cantidad (Real) | X3: Precio prom | Y3: Valor compra | Z3: Precio actual | AA3: Dividendos | AB3: Valor actual | AC3: Variación (%) | AD3: Variación ($) | AE3: Proporción cartera
A4: SPY | B4: BALANZ | C4: 1 | D4: =IF(A4=0,"...",VLOOKUP(A4,'Info CEDEARs'!$A$1:$H$340,5,0)) -> 20 | E4: =IF(A4=0,"...",C4/D4) -> 0.05 | F4: 45490 | G4: 1306 | H4: 36575 | I4: =IF(H4=0,"...",H4*(1+$H$2)/G4*D4) -> 563.46784 | J4: =IF(H4=0,"...",I4*E4) -> 28.173392 | K4: =IF(A4=0,"...",TODAY()) -> 46096 | L4: =IFERROR(__xludf.DUMMYFUNCTION("IF(A4=0, ""..."", (GOOGLEFINANCE(A4)*(1-$H$2) ))"),658.3162599999999) -> 658.31626 | N4: =IF(A4=0,"...",(L4)*E4+M4) -> 32.915813 | O4: =IF(H4=0,"...",(K4-F4)) -> 606 | P4: =IF(H4=0,"...",N4/J4-1) -> 0.16832978 | Q4: =IF(H4=0,"...",N4-J4) -> 4.742421 | R4: =IF(H4=0,"...",N4/$N$28) -> #DIV/0! | T4: {=UNIQUE($A$4:$A$27)} -> SPY | U4: =IF(T4=0, "...", SUMIF($A$4:$A$27, T4, $C$4:$C$27)) -> 1 | V4: =IF(T4=0,"...",IFERROR(VLOOKUP(T4,'Info CEDEARs'!$A$1:$H$340,5,0),1)) -> 20 | W4: =IF(T4=0,"...",U4/V4) -> 0.05 | X4: =IF(T4=0,"...",Y4/W4) -> 563.46784 | Y4: =IF(T4=0,"...",(SUMIF($A$4:$A$27,T4,$J$4:$J$27))) -> 28.173392 | Z4: =IFERROR(__xludf.DUMMYFUNCTION("IF(T4=0, ""..."", IF(W4=""No Aplica"", GOOGLEFINANCE(T4)/#REF!, IF(T4=""BBAR"", GOOGLEFINANCE(""BCBA:""&T4)/#REF!*V4, GOOGLEFINANCE(T4)*(1-$H$2)) ))"),658.3162599999999) -> 658.31626 | AA4: =IF(T4=0,"...",(SUMIF($A$4:$A$27,T4,$M$4:$M$27))) -> 0 | AB4: =IF(T4=0,"...",(SUMIF($A$4:$A$27,T4,$N$4:$N$27))) -> 32.915813 | AC4: =IF(T4=0,"...",AB4/Y4-1) -> 0.16832978 | AD4: =IF(T4=0,"...",AB4-Y4) -> 4.742421 | AE4: =IFERROR(AB4/$AB$20,0) -> 0
A5: QQQ | B5: BALANZ | C5: 1 | D5: =IF(A5=0,"...",VLOOKUP(A5,'Info CEDEARs'!$A$1:$H$340,5,0)) -> 20 | E5: =IF(A5=0,"...",C5/D5) -> 0.05 | F5: 45490 | G5: 1306 | H5: 31700 | I5: =IF(H5=0,"...",H5*(1+$H$2)/G5*D5) -> 488.36447 | J5: =IF(H5=0,"...",I5*E5) -> 24.418224 | K5: =IF(A5=0,"...",TODAY()) -> 46096 | L5: =IFERROR(__xludf.DUMMYFUNCTION("IF(A5=0, ""..."", (GOOGLEFINANCE(A5)*(1-$H$2) ))"),590.15768) -> 590.15768 | N5: =IF(A5=0,"...",(L5)*E5+M5) -> 29.507884 | O5: =IF(H5=0,"...",(K5-F5)) -> 606 | P5: =IF(H5=0,"...",N5/J5-1) -> 0.20843697 | Q5: =IF(H5=0,"...",N5-J5) -> 5.0896604 | R5: =IF(H5=0,"...",N5/$N$28) -> #DIV/0! | T5: QQQ | U5: =IF(T5=0, "...", SUMIF($A$4:$A$27, T5, $C$4:$C$27)) -> 2 | V5: =IF(T5=0,"...",IFERROR(VLOOKUP(T5,'Info CEDEARs'!$A$1:$H$340,5,0),1)) -> 20 | W5: =IF(T5=0,"...",U5/V5) -> 0.1 | X5: =IF(T5=0,"...",Y5/W5) -> 486.2317 | Y5: =IF(T5=0,"...",(SUMIF($A$4:$A$27,T5,$J$4:$J$27))) -> 48.62317 | Z5: =IFERROR(__xludf.DUMMYFUNCTION("IF(T5=0, ""..."", IF(W5=""No Aplica"", GOOGLEFINANCE(T5)/#REF!, IF(T5=""BBAR"", GOOGLEFINANCE(""BCBA:""&T5)/#REF!*V5, GOOGLEFINANCE(T5)*(1-$H$2)) ))"),590.15768) -> 590.15768 | AA5: =IF(T5=0,"...",(SUMIF($A$4:$A$27,T5,$M$4:$M$27))) -> 0 | AB5: =IF(T5=0,"...",(SUMIF($A$4:$A$27,T5,$N$4:$N$27))) -> 59.015768 | AC5: =IF(T5=0,"...",AB5/Y5-1) -> 0.21373757 | AD5: =IF(T5=0,"...",AB5-Y5) -> 10.392598 | AE5: =IFERROR(AB5/$AB$20,0) -> 0
A6: PFE | B6: BALANZ | C6: 1 | D6: =IF(A6=0,"...",VLOOKUP(A6,'Info CEDEARs'!$A$1:$H$340,5,0)) -> 4 | E6: =IF(A6=0,"...",C6/D6) -> 0.25 | F6: 45520 | G6: 1277 | H6: 9050 | I6: =IF(H6=0,"...",H6*(1+$H$2)/G6*D6) -> 28.517776 | J6: =IF(H6=0,"...",I6*E6) -> 7.129444 | K6: =IF(A6=0,"...",TODAY()) -> 46096 | L6: =IFERROR(__xludf.DUMMYFUNCTION("IF(A6=0, ""..."", (GOOGLEFINANCE(A6)*(1-$H$2) ))"),26.42052) -> 26.42052 | N6: =IF(A6=0,"...",(L6)*E6+M6) -> 6.60513 | O6: =IF(H6=0,"...",(K6-F6)) -> 576 | P6: =IF(H6=0,"...",N6/J6-1) -> -0.073542061 | Q6: =IF(H6=0,"...",N6-J6) -> -0.52431401 | R6: =IF(H6=0,"...",N6/$N$28) -> #DIV/0! | T6: PFE | U6: =IF(T6=0, "...", SUMIF($A$4:$A$27, T6, $C$4:$C$27)) -> 8 | V6: =IF(T6=0,"...",IFERROR(VLOOKUP(T6,'Info CEDEARs'!$A$1:$H$340,5,0),1)) -> 4 | W6: =IF(T6=0,"...",U6/V6) -> 2 | X6: =IF(T6=0,"...",Y6/W6) -> 29.40519 | Y6: =IF(T6=0,"...",(SUMIF($A$4:$A$27,T6,$J$4:$J$27))) -> 58.81038 | Z6: =IFERROR(__xludf.DUMMYFUNCTION("IF(T6=0, ""..."", IF(W6=""No Aplica"", GOOGLEFINANCE(T6)/#REF!, IF(T6=""BBAR"", GOOGLEFINANCE(""BCBA:""&T6)/#REF!*V6, GOOGLEFINANCE(T6)*(1-$H$2)) ))"),26.42052) -> 26.42052 | AA6: =IF(T6=0,"...",(SUMIF($A$4:$A$27,T6,$M$4:$M$27))) -> 0 | AB6: =IF(T6=0,"...",(SUMIF($A$4:$A$27,T6,$N$4:$N$27))) -> 52.84104 | AC6: =IF(T6=0,"...",AB6/Y6-1) -> -0.10150146 | AD6: =IF(T6=0,"...",AB6-Y6) -> -5.9693396 | AE6: =IFERROR(AB6/$AB$20,0) -> 0
A7: PFE | B7: BALANZ | C7: 7 | D7: =IF(A7=0,"...",VLOOKUP(A7,'Info CEDEARs'!$A$1:$H$340,5,0)) -> 4 | E7: =IF(A7=0,"...",C7/D7) -> 1.75 | F7: 45537 | G7: 1304 | H7: 9570 | I7: =IF(H7=0,"...",H7*(1+$H$2)/G7*D7) -> 29.531963 | J7: =IF(H7=0,"...",I7*E7) -> 51.680936 | K7: =IF(A7=0,"...",TODAY()) -> 46096 | L7: =IFERROR(__xludf.DUMMYFUNCTION("IF(A7=0, ""..."", (GOOGLEFINANCE(A7)*(1-$H$2) ))"),26.42052) -> 26.42052 | N7: =IF(A7=0,"...",(L7)*E7+M7) -> 46.23591 | O7: =IF(H7=0,"...",(K7-F7)) -> 559 | P7: =IF(H7=0,"...",N7/J7-1) -> -0.10535849 | Q7: =IF(H7=0,"...",N7-J7) -> -5.4450256 | R7: =IF(H7=0,"...",N7/$N$28) -> #DIV/0! | T7: TSLA | U7: =IF(T7=0, "...", SUMIF($A$4:$A$27, T7, $C$4:$C$27)) -> 6 | V7: =IF(T7=0,"...",IFERROR(VLOOKUP(T7,'Info CEDEARs'!$A$1:$H$340,5,0),1)) -> 15 | W7: =IF(T7=0,"...",U7/V7) -> 0.4 | X7: =IF(T7=0,"...",Y7/W7) -> 250.76003 | Y7: =IF(T7=0,"...",(SUMIF($A$4:$A$27,T7,$J$4:$J$27))) -> 100.30401 | Z7: =IFERROR(__xludf.DUMMYFUNCTION("IF(T7=0, ""..."", IF(W7=""No Aplica"", GOOGLEFINANCE(T7)/#REF!, IF(T7=""BBAR"", GOOGLEFINANCE(""BCBA:""&T7)/#REF!*V7, GOOGLEFINANCE(T7)*(1-$H$2)) ))"),388.8528) -> 388.8528 | AA7: =IF(T7=0,"...",(SUMIF($A$4:$A$27,T7,$M$4:$M$27))) -> 0 | AB7: =IF(T7=0,"...",(SUMIF($A$4:$A$27,T7,$N$4:$N$27))) -> 155.54112 | AC7: =IF(T7=0,"...",AB7/Y7-1) -> 0.55069691 | AD7: =IF(T7=0,"...",AB7-Y7) -> 55.237109 | AE7: =IFERROR(AB7/$AB$20,0) -> 0
A8: QQQ | B8: BALANZ | C8: 1 | D8: =IF(A8=0,"...",VLOOKUP(A8,'Info CEDEARs'!$A$1:$H$340,5,0)) -> 20 | E8: =IF(A8=0,"...",C8/D8) -> 0.05 | F8: 45537 | G8: 1304 | H8: 31375 | I8: =IF(H8=0,"...",H8*(1+$H$2)/G8*D8) -> 484.09893 | J8: =IF(H8=0,"...",I8*E8) -> 24.204946 | K8: =IF(A8=0,"...",TODAY()) -> 46096 | L8: =IFERROR(__xludf.DUMMYFUNCTION("IF(A8=0, ""..."", (GOOGLEFINANCE(A8)*(1-$H$2) ))"),590.15768) -> 590.15768 | N8: =IF(A8=0,"...",(L8)*E8+M8) -> 29.507884 | O8: =IF(H8=0,"...",(K8-F8)) -> 559 | P8: =IF(H8=0,"...",N8/J8-1) -> 0.21908488 | Q8: =IF(H8=0,"...",N8-J8) -> 5.3029377 | R8: =IF(H8=0,"...",N8/$N$28) -> #DIV/0! | T8: NU | U8: =IF(T8=0, "...", SUMIF($A$4:$A$27, T8, $C$4:$C$27)) -> 6 | V8: =IF(T8=0,"...",IFERROR(VLOOKUP(T8,'Info CEDEARs'!$A$1:$H$340,5,0),1)) | W8: =IF(T8=0,"...",U8/V8) -> #DIV/0! | X8: =IF(T8=0,"...",Y8/W8) -> #DIV/0! | Y8: =IF(T8=0,"...",(SUMIF($A$4:$A$27,T8,$J$4:$J$27))) -> 0 | Z8: =IFERROR(__xludf.DUMMYFUNCTION("IF(T8=0, ""..."", IF(W8=""No Aplica"", GOOGLEFINANCE(T8)/#REF!, IF(T8=""BBAR"", GOOGLEFINANCE(""BCBA:""&T8)/#REF!*V8, GOOGLEFINANCE(T8)*(1-$H$2)) ))"),"#DIV/0!") -> #DIV/0! | AA8: =IF(T8=0,"...",(SUMIF($A$4:$A$27,T8,$M$4:$M$27))) -> 0 | AB8: =IF(T8=0,"...",(SUMIF($A$4:$A$27,T8,$N$4:$N$27))) -> #DIV/0! | AC8: =IF(T8=0,"...",AB8/Y8-1) -> #DIV/0! | AD8: =IF(T8=0,"...",AB8-Y8) -> #DIV/0! | AE8: =IFERROR(AB8/$AB$20,0) -> 0
A9: TSLA | B9: BALANZ | C9: 4 | D9: =IF(A9=0,"...",VLOOKUP(A9,'Info CEDEARs'!$A$1:$H$340,5,0)) -> 15 | E9: =IF(A9=0,"...",C9/D9) -> 0.26666667 | F9: 45729 | G9: 1235 | H9: 19450 | I9: =IF(H9=0,"...",H9*(1+$H$2)/G9*D9) -> 237.65223 | J9: =IF(H9=0,"...",I9*E9) -> 63.373927 | K9: =IF(A9=0,"...",TODAY()) -> 46096 | L9: =IFERROR(__xludf.DUMMYFUNCTION("IF(A9=0, ""..."", (GOOGLEFINANCE(A9)*(1-$H$2) ))"),388.8528) -> 388.8528 | N9: =IF(A9=0,"...",(L9)*E9+M9) -> 103.69408 | O9: =IF(H9=0,"...",(K9-F9)) -> 367 | P9: =IF(H9=0,"...",N9/J9-1) -> 0.6362262 | Q9: =IF(H9=0,"...",N9-J9) -> 40.320153 | R9: =IF(H9=0,"...",N9/$N$28) -> #DIV/0! | U9: =IF(T9=0, "...", SUMIF($A$4:$A$27, T9, $C$4:$C$27)) -> ... | V9: =IF(T9=0,"...",IFERROR(VLOOKUP(T9,'Info CEDEARs'!$A$1:$H$340,5,0),1)) -> ... | W9: =IF(T9=0,"...",U9/V9) -> ... | X9: =IF(T9=0,"...",Y9/W9) -> ... | Y9: =IF(T9=0,"...",(SUMIF($A$4:$A$27,T9,$J$4:$J$27))) -> ... | Z9: =IFERROR(__xludf.DUMMYFUNCTION("IF(T9=0, ""..."", IF(W9=""No Aplica"", GOOGLEFINANCE(T9)/#REF!, IF(T9=""BBAR"", GOOGLEFINANCE(""BCBA:""&T9)/#REF!*V9, GOOGLEFINANCE(T9)*(1-$H$2)) ))"),"...") -> ... | AA9: =IF(T9=0,"...",(SUMIF($A$4:$A$27,T9,$M$4:$M$27))) -> ... | AB9: =IF(T9=0,"...",(SUMIF($A$4:$A$27,T9,$N$4:$N$27))) -> ... | AC9: =IF(T9=0,"...",AB9/Y9-1) -> ... | AD9: =IF(T9=0,"...",AB9-Y9) -> ... | AE9: =IFERROR(AB9/$AB$20,0) -> 0
A10: TSLA | B10: BALANZ | C10: 2 | D10: =IF(A10=0,"...",VLOOKUP(A10,'Info CEDEARs'!$A$1:$H$340,5,0)) -> 15 | E10: =IF(A10=0,"...",C10/D10) -> 0.13333333 | F10: Abr 1, 2025 | G10: 1313 | H10: 24100 | I10: =IF(H10=0,"...",H10*(1+$H$2)/G10*D10) -> 276.97563 | J10: =IF(H10=0,"...",I10*E10) -> 36.930084 | K10: =IF(A10=0,"...",TODAY()) -> 46096 | L10: =IFERROR(__xludf.DUMMYFUNCTION("IF(A10=0, ""..."", (GOOGLEFINANCE(A10)*(1-$H$2) ))"),388.8528) -> 388.8528 | N10: =IF(A10=0,"...",(L10)*E10+M10) -> 51.84704 | O10: =IF(H10=0,"...",(K10-F10)) -> #VALUE! | P10: =IF(H10=0,"...",N10/J10-1) -> 0.40392425 | Q10: =IF(H10=0,"...",N10-J10) -> 14.916956 | R10: =IF(H10=0,"...",N10/$N$28) -> #DIV/0! | U10: =IF(T10=0, "...", SUMIF($A$4:$A$27, T10, $C$4:$C$27)) -> ... | V10: =IF(T10=0,"...",IFERROR(VLOOKUP(T10,'Info CEDEARs'!$A$1:$H$340,5,0),1)) -> ... | W10: =IF(T10=0,"...",U10/V10) -> ... | X10: =IF(T10=0,"...",Y10/W10) -> ... | Y10: =IF(T10=0,"...",(SUMIF($A$4:$A$27,T10,$J$4:$J$27))) -> ... | Z10: =IFERROR(__xludf.DUMMYFUNCTION("IF(T10=0, ""..."", IF(W10=""No Aplica"", GOOGLEFINANCE(T10)/#REF!, IF(T10=""BBAR"", GOOGLEFINANCE(""BCBA:""&T10)/#REF!*V10, GOOGLEFINANCE(T10)*(1-$H$2)) ))"),"...") -> ... | AA10: =IF(T10=0,"...",(SUMIF($A$4:$A$27,T10,$M$4:$M$27))) -> ... | AB10: =IF(T10=0,"...",(SUMIF($A$4:$A$27,T10,$N$4:$N$27))) -> ... | AC10: =IF(T10=0,"...",AB10/Y10-1) -> ... | AD10: =IF(T10=0,"...",AB10-Y10) -> ... | AE10: =IFERROR(AB10/$AB$20,0) -> 0
A11: NU | B11: BALANZ | C11: 6 | D11: =IF(A11=0,"...",VLOOKUP(A11,'Info CEDEARs'!$A$1:$H$340,5,0)) | E11: =IF(A11=0,"...",C11/D11) -> #DIV/0! | I11: =IF(H11=0,"...",H11*(1+$H$2)/G11*D11) -> ... | J11: =IF(H11=0,"...",I11*E11) -> ... | K11: =IF(A11=0,"...",TODAY()) -> 46096 | L11: =IFERROR(__xludf.DUMMYFUNCTION("IF(A11=0, ""..."", (GOOGLEFINANCE(A11)*(1-$H$2) ))"),13.80666) -> 13.80666 | N11: =IF(A11=0,"...",(L11)*E11+M11) -> #DIV/0! | O11: =IF(H11=0,"...",(K11-F11)) -> ... | P11: =IF(H11=0,"...",N11/J11-1) -> ... | Q11: =IF(H11=0,"...",N11-J11) -> ... | R11: =IF(H11=0,"...",N11/$N$28) -> ... | U11: =IF(T11=0, "...", SUMIF($A$4:$A$27, T11, $C$4:$C$27)) -> ... | V11: =IF(T11=0,"...",IFERROR(VLOOKUP(T11,'Info CEDEARs'!$A$1:$H$340,5,0),1)) -> ... | W11: =IF(T11=0,"...",U11/V11) -> ... | X11: =IF(T11=0,"...",Y11/W11) -> ... | Y11: =IF(T11=0,"...",(SUMIF($A$4:$A$27,T11,$J$4:$J$27))) -> ... | Z11: =IFERROR(__xludf.DUMMYFUNCTION("IF(T11=0, ""..."", IF(W11=""No Aplica"", GOOGLEFINANCE(T11)/#REF!, IF(T11=""BBAR"", GOOGLEFINANCE(""BCBA:""&T11)/#REF!*V11, GOOGLEFINANCE(T11)*(1-$H$2)) ))"),"...") -> ... | AA11: =IF(T11=0,"...",(SUMIF($A$4:$A$27,T11,$M$4:$M$27))) -> ... | AB11: =IF(T11=0,"...",(SUMIF($A$4:$A$27,T11,$N$4:$N$27))) -> ... | AC11: =IF(T11=0,"...",AB11/Y11-1) -> ... | AD11: =IF(T11=0,"...",AB11-Y11) -> ... | AE11: =IFERROR(AB11/$AB$20,0) -> 0
D12: =IF(A12=0,"...",VLOOKUP(A12,'Info CEDEARs'!$A$1:$H$340,5,0)) -> ... | E12: =IF(A12=0,"...",C12/D12) -> ... | I12: =IF(H12=0,"...",H12*(1+$H$2)/G12*D12) -> ... | J12: =IF(H12=0,"...",I12*E12) -> ... | K12: =IF(A12=0,"...",TODAY()) -> ... | L12: =IFERROR(__xludf.DUMMYFUNCTION("IF(A12=0, ""..."", (GOOGLEFINANCE(A12)*(1-$H$2) ))"),"...") -> ... | N12: =IF(A12=0,"...",(L12)*E12+M12) -> ... | O12: =IF(H12=0,"...",(K12-F12)) -> ... | P12: =IF(H12=0,"...",N12/J12-1) -> ... | Q12: =IF(H12=0,"...",N12-J12) -> ... | R12: =IF(H12=0,"...",N12/$N$28) -> ... | U12: =IF(T12=0, "...", SUMIF($A$4:$A$27, T12, $C$4:$C$27)) -> ... | V12: =IF(T12=0,"...",IFERROR(VLOOKUP(T12,'Info CEDEARs'!$A$1:$H$340,5,0),1)) -> ... | W12: =IF(T12=0,"...",U12/V12) -> ... | X12: =IF(T12=0,"...",Y12/W12) -> ... | Y12: =IF(T12=0,"...",(SUMIF($A$4:$A$27,T12,$J$4:$J$27))) -> ... | Z12: =IFERROR(__xludf.DUMMYFUNCTION("IF(T12=0, ""..."", IF(W12=""No Aplica"", GOOGLEFINANCE(T12)/#REF!, IF(T12=""BBAR"", GOOGLEFINANCE(""BCBA:""&T12)/#REF!*V12, GOOGLEFINANCE(T12)*(1-$H$2)) ))"),"...") -> ... | AA12: =IF(T12=0,"...",(SUMIF($A$4:$A$27,T12,$M$4:$M$27))) -> ... | AB12: =IF(T12=0,"...",(SUMIF($A$4:$A$27,T12,$N$4:$N$27))) -> ... | AC12: =IF(T12=0,"...",AB12/Y12-1) -> ... | AD12: =IF(T12=0,"...",AB12-Y12) -> ... | AE12: =IFERROR(AB12/$AB$20,0) -> 0
D13: =IF(A13=0,"...",VLOOKUP(A13,'Info CEDEARs'!$A$1:$H$340,5,0)) -> ... | E13: =IF(A13=0,"...",C13/D13) -> ... | I13: =IF(H13=0,"...",H13*(1+$H$2)/G13*D13) -> ... | J13: =IF(H13=0,"...",I13*E13) -> ... | K13: =IF(A13=0,"...",TODAY()) -> ... | L13: =IFERROR(__xludf.DUMMYFUNCTION("IF(A13=0, ""..."", (GOOGLEFINANCE(A13)*(1-$H$2) ))"),"...") -> ... | N13: =IF(A13=0,"...",(L13)*E13+M13) -> ... | O13: =IF(H13=0,"...",(K13-F13)) -> ... | P13: =IF(H13=0,"...",N13/J13-1) -> ... | Q13: =IF(H13=0,"...",N13-J13) -> ... | R13: =IF(H13=0,"...",N13/$N$28) -> ... | U13: =IF(T13=0, "...", SUMIF($A$4:$A$27, T13, $C$4:$C$27)) -> ... | V13: =IF(T13=0,"...",IFERROR(VLOOKUP(T13,'Info CEDEARs'!$A$1:$H$340,5,0),1)) -> ... | W13: =IF(T13=0,"...",U13/V13) -> ... | X13: =IF(T13=0,"...",Y13/W13) -> ... | Y13: =IF(T13=0,"...",(SUMIF($A$4:$A$27,T13,$J$4:$J$27))) -> ... | Z13: =IFERROR(__xludf.DUMMYFUNCTION("IF(T13=0, ""..."", IF(W13=""No Aplica"", GOOGLEFINANCE(T13)/#REF!, IF(T13=""BBAR"", GOOGLEFINANCE(""BCBA:""&T13)/#REF!*V13, GOOGLEFINANCE(T13)*(1-$H$2)) ))"),"...") -> ... | AA13: =IF(T13=0,"...",(SUMIF($A$4:$A$27,T13,$M$4:$M$27))) -> ... | AB13: =IF(T13=0,"...",(SUMIF($A$4:$A$27,T13,$N$4:$N$27))) -> ... | AC13: =IF(T13=0,"...",AB13/Y13-1) -> ... | AD13: =IF(T13=0,"...",AB13-Y13) -> ... | AE13: =IFERROR(AB13/$AB$20,0) -> 0
D14: =IF(A14=0,"...",VLOOKUP(A14,'Info CEDEARs'!$A$1:$H$340,5,0)) -> ... | E14: =IF(A14=0,"...",C14/D14) -> ... | I14: =IF(H14=0,"...",H14*(1+$H$2)/G14*D14) -> ... | J14: =IF(H14=0,"...",I14*E14) -> ... | K14: =IF(A14=0,"...",TODAY()) -> ... | L14: =IFERROR(__xludf.DUMMYFUNCTION("IF(A14=0, ""..."", (GOOGLEFINANCE(A14)*(1-$H$2) ))"),"...") -> ... | N14: =IF(A14=0,"...",(L14)*E14+M14) -> ... | O14: =IF(H14=0,"...",(K14-F14)) -> ... | P14: =IF(H14=0,"...",N14/J14-1) -> ... | Q14: =IF(H14=0,"...",N14-J14) -> ... | R14: =IF(H14=0,"...",N14/$N$28) -> ... | U14: =IF(T14=0, "...", SUMIF($A$4:$A$27, T14, $C$4:$C$27)) -> ... | V14: =IF(T14=0,"...",IFERROR(VLOOKUP(T14,'Info CEDEARs'!$A$1:$H$340,5,0),1)) -> ... | W14: =IF(T14=0,"...",U14/V14) -> ... | X14: =IF(T14=0,"...",Y14/W14) -> ... | Y14: =IF(T14=0,"...",(SUMIF($A$4:$A$27,T14,$J$4:$J$27))) -> ... | Z14: =IFERROR(__xludf.DUMMYFUNCTION("IF(T14=0, ""..."", IF(W14=""No Aplica"", GOOGLEFINANCE(T14)/#REF!, IF(T14=""BBAR"", GOOGLEFINANCE(""BCBA:""&T14)/#REF!*V14, GOOGLEFINANCE(T14)*(1-$H$2)) ))"),"...") -> ... | AA14: =IF(T14=0,"...",(SUMIF($A$4:$A$27,T14,$M$4:$M$27))) -> ... | AB14: =IF(T14=0,"...",(SUMIF($A$4:$A$27,T14,$N$4:$N$27))) -> ... | AC14: =IF(T14=0,"...",AB14/Y14-1) -> ... | AD14: =IF(T14=0,"...",AB14-Y14) -> ... | AE14: =IFERROR(AB14/$AB$20,0) -> 0
D15: =IF(A15=0,"...",VLOOKUP(A15,'Info CEDEARs'!$A$1:$H$340,5,0)) -> ... | E15: =IF(A15=0,"...",C15/D15) -> ... | I15: =IF(H15=0,"...",H15*(1+$H$2)/G15*D15) -> ... | J15: =IF(H15=0,"...",I15*E15) -> ... | K15: =IF(A15=0,"...",TODAY()) -> ... | L15: =IFERROR(__xludf.DUMMYFUNCTION("IF(A15=0, ""..."", (GOOGLEFINANCE(A15)*(1-$H$2) ))"),"...") -> ... | N15: =IF(A15=0,"...",(L15)*E15+M15) -> ... | O15: =IF(H15=0,"...",(K15-F15)) -> ... | P15: =IF(H15=0,"...",N15/J15-1) -> ... | Q15: =IF(H15=0,"...",N15-J15) -> ... | R15: =IF(H15=0,"...",N15/$N$28) -> ... | U15: =IF(T15=0, "...", SUMIF($A$4:$A$27, T15, $C$4:$C$27)) -> ... | V15: =IF(T15=0,"...",IFERROR(VLOOKUP(T15,'Info CEDEARs'!$A$1:$H$340,5,0),1)) -> ... | W15: =IF(T15=0,"...",U15/V15) -> ... | X15: =IF(T15=0,"...",Y15/W15) -> ... | Y15: =IF(T15=0,"...",(SUMIF($A$4:$A$27,T15,$J$4:$J$27))) -> ... | Z15: =IFERROR(__xludf.DUMMYFUNCTION("IF(T15=0, ""..."", IF(W15=""No Aplica"", GOOGLEFINANCE(T15)/#REF!, IF(T15=""BBAR"", GOOGLEFINANCE(""BCBA:""&T15)/#REF!*V15, GOOGLEFINANCE(T15)*(1-$H$2)) ))"),"...") -> ... | AA15: =IF(T15=0,"...",(SUMIF($A$4:$A$27,T15,$M$4:$M$27))) -> ... | AB15: =IF(T15=0,"...",(SUMIF($A$4:$A$27,T15,$N$4:$N$27))) -> ... | AC15: =IF(T15=0,"...",AB15/Y15-1) -> ... | AD15: =IF(T15=0,"...",AB15-Y15) -> ... | AE15: =IFERROR(AB15/$AB$20,0) -> 0
D16: =IF(A16=0,"...",VLOOKUP(A16,'Info CEDEARs'!$A$1:$H$340,5,0)) -> ... | E16: =IF(A16=0,"...",C16/D16) -> ... | I16: =IF(H16=0,"...",H16*(1+$H$2)/G16*D16) -> ... | J16: =IF(H16=0,"...",I16*E16) -> ... | K16: =IF(A16=0,"...",TODAY()) -> ... | L16: =IFERROR(__xludf.DUMMYFUNCTION("IF(A16=0, ""..."", (GOOGLEFINANCE(A16)*(1-$H$2) ))"),"...") -> ... | N16: =IF(A16=0,"...",(L16)*E16+M16) -> ... | O16: =IF(H16=0,"...",(K16-F16)) -> ... | P16: =IF(H16=0,"...",N16/J16-1) -> ... | Q16: =IF(H16=0,"...",N16-J16) -> ... | R16: =IF(H16=0,"...",N16/$N$28) -> ... | U16: =IF(T16=0, "...", SUMIF($A$4:$A$27, T16, $C$4:$C$27)) -> ... | V16: =IF(T16=0,"...",IFERROR(VLOOKUP(T16,'Info CEDEARs'!$A$1:$H$340,5,0),1)) -> ... | W16: =IF(T16=0,"...",U16/V16) -> ... | X16: =IF(T16=0,"...",Y16/W16) -> ... | Y16: =IF(T16=0,"...",(SUMIF($A$4:$A$27,T16,$J$4:$J$27))) -> ... | Z16: =IFERROR(__xludf.DUMMYFUNCTION("IF(T16=0, ""..."", IF(W16=""No Aplica"", GOOGLEFINANCE(T16)/#REF!, IF(T16=""BBAR"", GOOGLEFINANCE(""BCBA:""&T16)/#REF!*V16, GOOGLEFINANCE(T16)*(1-$H$2)) ))"),"...") -> ... | AA16: =IF(T16=0,"...",(SUMIF($A$4:$A$27,T16,$M$4:$M$27))) -> ... | AB16: =IF(T16=0,"...",(SUMIF($A$4:$A$27,T16,$N$4:$N$27))) -> ... | AC16: =IF(T16=0,"...",AB16/Y16-1) -> ... | AD16: =IF(T16=0,"...",AB16-Y16) -> ... | AE16: =IFERROR(AB16/$AB$20,0) -> 0
D17: =IF(A17=0,"...",VLOOKUP(A17,'Info CEDEARs'!$A$1:$H$340,5,0)) -> ... | E17: =IF(A17=0,"...",C17/D17) -> ... | I17: =IF(H17=0,"...",H17*(1+$H$2)/G17*D17) -> ... | J17: =IF(H17=0,"...",I17*E17) -> ... | K17: =IF(A17=0,"...",TODAY()) -> ... | L17: =IFERROR(__xludf.DUMMYFUNCTION("IF(A17=0, ""..."", (GOOGLEFINANCE(A17)*(1-$H$2) ))"),"...") -> ... | N17: =IF(A17=0,"...",(L17)*E17+M17) -> ... | O17: =IF(H17=0,"...",(K17-F17)) -> ... | P17: =IF(H17=0,"...",N17/J17-1) -> ... | Q17: =IF(H17=0,"...",N17-J17) -> ... | R17: =IF(H17=0,"...",N17/$N$28) -> ... | U17: =IF(T17=0, "...", SUMIF($A$4:$A$27, T17, $C$4:$C$27)) -> ... | V17: =IF(T17=0,"...",IFERROR(VLOOKUP(T17,'Info CEDEARs'!$A$1:$H$340,5,0),1)) -> ... | W17: =IF(T17=0,"...",U17/V17) -> ... | X17: =IF(T17=0,"...",Y17/W17) -> ... | Y17: =IF(T17=0,"...",(SUMIF($A$4:$A$27,T17,$J$4:$J$27))) -> ... | Z17: =IFERROR(__xludf.DUMMYFUNCTION("IF(T17=0, ""..."", IF(W17=""No Aplica"", GOOGLEFINANCE(T17)/#REF!, IF(T17=""BBAR"", GOOGLEFINANCE(""BCBA:""&T17)/#REF!*V17, GOOGLEFINANCE(T17)*(1-$H$2)) ))"),"...") -> ... | AA17: =IF(T17=0,"...",(SUMIF($A$4:$A$27,T17,$M$4:$M$27))) -> ... | AB17: =IF(T17=0,"...",(SUMIF($A$4:$A$27,T17,$N$4:$N$27))) -> ... | AC17: =IF(T17=0,"...",AB17/Y17-1) -> ... | AD17: =IF(T17=0,"...",AB17-Y17) -> ... | AE17: =IFERROR(AB17/$AB$20,0) -> 0
D18: =IF(A18=0,"...",VLOOKUP(A18,'Info CEDEARs'!$A$1:$H$340,5,0)) -> ... | E18: =IF(A18=0,"...",C18/D18) -> ... | I18: =IF(H18=0,"...",H18*(1+$H$2)/G18*D18) -> ... | J18: =IF(H18=0,"...",I18*E18) -> ... | K18: =IF(A18=0,"...",TODAY()) -> ... | L18: =IFERROR(__xludf.DUMMYFUNCTION("IF(A18=0, ""..."", (GOOGLEFINANCE(A18)*(1-$H$2) ))"),"...") -> ... | N18: =IF(A18=0,"...",(L18)*E18+M18) -> ... | O18: =IF(H18=0,"...",(K18-F18)) -> ... | P18: =IF(H18=0,"...",N18/J18-1) -> ... | Q18: =IF(H18=0,"...",N18-J18) -> ... | R18: =IF(H18=0,"...",N18/$N$28) -> ... | U18: =IF(T18=0, "...", SUMIF($A$4:$A$27, T18, $C$4:$C$27)) -> ... | V18: =IF(T18=0,"...",IFERROR(VLOOKUP(T18,'Info CEDEARs'!$A$1:$H$340,5,0),1)) -> ... | W18: =IF(T18=0,"...",U18/V18) -> ... | X18: =IF(T18=0,"...",Y18/W18) -> ... | Y18: =IF(T18=0,"...",(SUMIF($A$4:$A$27,T18,$J$4:$J$27))) -> ... | Z18: =IFERROR(__xludf.DUMMYFUNCTION("IF(T18=0, ""..."", IF(W18=""No Aplica"", GOOGLEFINANCE(T18)/#REF!, IF(T18=""BBAR"", GOOGLEFINANCE(""BCBA:""&T18)/#REF!*V18, GOOGLEFINANCE(T18)*(1-$H$2)) ))"),"...") -> ... | AA18: =IF(T18=0,"...",(SUMIF($A$4:$A$27,T18,$M$4:$M$27))) -> ... | AB18: =IF(T18=0,"...",(SUMIF($A$4:$A$27,T18,$N$4:$N$27))) -> ... | AC18: =IF(T18=0,"...",AB18/Y18-1) -> ... | AD18: =IF(T18=0,"...",AB18-Y18) -> ... | AE18: =IFERROR(AB18/$AB$20,0) -> 0
D19: =IF(A19=0,"...",VLOOKUP(A19,'Info CEDEARs'!$A$1:$H$340,5,0)) -> ... | E19: =IF(A19=0,"...",C19/D19) -> ... | I19: =IF(H19=0,"...",H19*(1+$H$2)/G19*D19) -> ... | J19: =IF(H19=0,"...",I19*E19) -> ... | K19: =IF(A19=0,"...",TODAY()) -> ... | L19: =IFERROR(__xludf.DUMMYFUNCTION("IF(A19=0, ""..."", (GOOGLEFINANCE(A19)*(1-$H$2) ))"),"...") -> ... | N19: =IF(A19=0,"...",(L19)*E19+M19) -> ... | O19: =IF(H19=0,"...",(K19-F19)) -> ... | P19: =IF(H19=0,"...",N19/J19-1) -> ... | Q19: =IF(H19=0,"...",N19-J19) -> ... | R19: =IF(H19=0,"...",N19/$N$28) -> ... | U19: =IF(T19=0, "...", SUMIF($A$4:$A$27, T19, $C$4:$C$27)) -> ... | V19: =IF(T19=0,"...",IFERROR(VLOOKUP(T19,'Info CEDEARs'!$A$1:$H$340,5,0),1)) -> ... | W19: =IF(T19=0,"...",U19/V19) -> ... | X19: =IF(T19=0,"...",Y19/W19) -> ... | Y19: =IF(T19=0,"...",(SUMIF($A$4:$A$27,T19,$J$4:$J$27))) -> ... | Z19: =IFERROR(__xludf.DUMMYFUNCTION("IF(T19=0, ""..."", IF(W19=""No Aplica"", GOOGLEFINANCE(T19)/#REF!, IF(T19=""BBAR"", GOOGLEFINANCE(""BCBA:""&T19)/#REF!*V19, GOOGLEFINANCE(T19)*(1-$H$2)) ))"),"...") -> ... | AA19: =IF(T19=0,"...",(SUMIF($A$4:$A$27,T19,$M$4:$M$27))) -> ... | AB19: =IF(T19=0,"...",(SUMIF($A$4:$A$27,T19,$N$4:$N$27))) -> ... | AC19: =IF(T19=0,"...",AB19/Y19-1) -> ... | AD19: =IF(T19=0,"...",AB19-Y19) -> ... | AE19: =IFERROR(AB19/$AB$20,0) -> 0
D20: =IF(A20=0,"...",VLOOKUP(A20,'Info CEDEARs'!$A$1:$H$340,5,0)) -> ... | E20: =IF(A20=0,"...",C20/D20) -> ... | I20: =IF(H20=0,"...",H20*(1+$H$2)/G20*D20) -> ... | J20: =IF(H20=0,"...",I20*E20) -> ... | K20: =IF(A20=0,"...",TODAY()) -> ... | L20: =IFERROR(__xludf.DUMMYFUNCTION("IF(A20=0, ""..."", (GOOGLEFINANCE(A20)*(1-$H$2) ))"),"...") -> ... | N20: =IF(A20=0,"...",(L20)*E20+M20) -> ... | O20: =IF(H20=0,"...",(K20-F20)) -> ... | P20: =IF(H20=0,"...",N20/J20-1) -> ... | Q20: =IF(H20=0,"...",N20-J20) -> ... | R20: =IF(H20=0,"...",N20/$N$28) -> ... | T20: TOTAL | Y20: =IF(SUM(Y$4:Y19)=0,"...",SUM(Y$4:Y19)) -> 235.91095 | AA20: =IF(Y20="...","...",SUM($AB$4:$AB19)) -> #DIV/0! | AB20: =IF(Y20="...","...",SUM($AB$4:$AB19)) -> #DIV/0! | AC20: =IF(Y20="...","...",AB20/Y20-1) -> #DIV/0! | AD20: =IF(Y20="...","...",SUM(AD$4:AD19)) -> #DIV/0! | AE20: =IF(Y20="...","...",AB20/AB20) -> #DIV/0!
D21: =IF(A21=0,"...",VLOOKUP(A21,'Info CEDEARs'!$A$1:$H$340,5,0)) -> ... | E21: =IF(A21=0,"...",C21/D21) -> ... | I21: =IF(H21=0,"...",H21*(1+$H$2)/G21*D21) -> ... | J21: =IF(H21=0,"...",I21*E21) -> ... | K21: =IF(A21=0,"...",TODAY()) -> ... | L21: =IFERROR(__xludf.DUMMYFUNCTION("IF(A21=0, ""..."", (GOOGLEFINANCE(A21)*(1-$H$2) ))"),"...") -> ... | N21: =IF(A21=0,"...",(L21)*E21+M21) -> ... | O21: =IF(H21=0,"...",(K21-F21)) -> ... | P21: =IF(H21=0,"...",N21/J21-1) -> ... | Q21: =IF(H21=0,"...",N21-J21) -> ... | R21: =IF(H21=0,"...",N21/$N$28) -> ...
D22: =IF(A22=0,"...",VLOOKUP(A22,'Info CEDEARs'!$A$1:$H$340,5,0)) -> ... | E22: =IF(A22=0,"...",C22/D22) -> ... | I22: =IF(H22=0,"...",H22*(1+$H$2)/G22*D22) -> ... | J22: =IF(H22=0,"...",I22*E22) -> ... | K22: =IF(A22=0,"...",TODAY()) -> ... | L22: =IFERROR(__xludf.DUMMYFUNCTION("IF(A22=0, ""..."", (GOOGLEFINANCE(A22)*(1-$H$2) ))"),"...") -> ... | N22: =IF(A22=0,"...",(L22)*E22+M22) -> ... | O22: =IF(H22=0,"...",(K22-F22)) -> ... | P22: =IF(H22=0,"...",N22/J22-1) -> ... | Q22: =IF(H22=0,"...",N22-J22) -> ... | R22: =IF(H22=0,"...",N22/$N$28) -> ...
D23: =IF(A23=0,"...",VLOOKUP(A23,'Info CEDEARs'!$A$1:$H$340,5,0)) -> ... | E23: =IF(A23=0,"...",C23/D23) -> ... | I23: =IF(H23=0,"...",H23*(1+$H$2)/G23*D23) -> ... | J23: =IF(H23=0,"...",I23*E23) -> ... | K23: =IF(A23=0,"...",TODAY()) -> ... | L23: =IFERROR(__xludf.DUMMYFUNCTION("IF(A23=0, ""..."", (GOOGLEFINANCE(A23)*(1-$H$2) ))"),"...") -> ... | N23: =IF(A23=0,"...",(L23)*E23+M23) -> ... | O23: =IF(H23=0,"...",(K23-F23)) -> ... | P23: =IF(H23=0,"...",N23/J23-1) -> ... | Q23: =IF(H23=0,"...",N23-J23) -> ... | R23: =IF(H23=0,"...",N23/$N$28) -> ...
D24: =IF(A24=0,"...",VLOOKUP(A24,'Info CEDEARs'!$A$1:$H$340,5,0)) -> ... | E24: =IF(A24=0,"...",C24/D24) -> ... | I24: =IF(H24=0,"...",H24*(1+$H$2)/G24*D24) -> ... | J24: =IF(H24=0,"...",I24*E24) -> ... | K24: =IF(A24=0,"...",TODAY()) -> ... | L24: =IFERROR(__xludf.DUMMYFUNCTION("IF(A24=0, ""..."", (GOOGLEFINANCE(A24)*(1-$H$2) ))"),"...") -> ... | N24: =IF(A24=0,"...",(L24)*E24+M24) -> ... | O24: =IF(H24=0,"...",(K24-F24)) -> ... | P24: =IF(H24=0,"...",N24/J24-1) -> ... | Q24: =IF(H24=0,"...",N24-J24) -> ... | R24: =IF(H24=0,"...",N24/$N$28) -> ...
D25: =IF(A25=0,"...",VLOOKUP(A25,'Info CEDEARs'!$A$1:$H$340,5,0)) -> ... | E25: =IF(A25=0,"...",C25/D25) -> ... | I25: =IF(H25=0,"...",H25*(1+$H$2)/G25*D25) -> ... | J25: =IF(H25=0,"...",I25*E25) -> ... | K25: =IF(A25=0,"...",TODAY()) -> ... | L25: =IFERROR(__xludf.DUMMYFUNCTION("IF(A25=0, ""..."", (GOOGLEFINANCE(A25)*(1-$H$2) ))"),"...") -> ... | N25: =IF(A25=0,"...",(L25)*E25+M25) -> ... | O25: =IF(H25=0,"...",(K25-F25)) -> ... | P25: =IF(H25=0,"...",N25/J25-1) -> ... | Q25: =IF(H25=0,"...",N25-J25) -> ... | R25: =IF(H25=0,"...",N25/$N$28) -> ...
D26: =IF(A26=0,"...",VLOOKUP(A26,'Info CEDEARs'!$A$1:$H$340,5,0)) -> ... | E26: =IF(A26=0,"...",C26/D26) -> ... | I26: =IF(H26=0,"...",H26*(1+$H$2)/G26*D26) -> ... | J26: =IF(H26=0,"...",I26*E26) -> ... | K26: =IF(A26=0,"...",TODAY()) -> ... | L26: =IFERROR(__xludf.DUMMYFUNCTION("IF(A26=0, ""..."", (GOOGLEFINANCE(A26)*(1-$H$2) ))"),"...") -> ... | N26: =IF(A26=0,"...",(L26)*E26+M26) -> ... | O26: =IF(H26=0,"...",(K26-F26)) -> ... | P26: =IF(H26=0,"...",N26/J26-1) -> ... | Q26: =IF(H26=0,"...",N26-J26) -> ... | R26: =IF(H26=0,"...",N26/$N$28) -> ...
D27: =IF(A27=0,"...",VLOOKUP(A27,'Info CEDEARs'!$A$1:$H$340,5,0)) -> ... | E27: =IF(A27=0,"...",C27/D27) -> ... | I27: =IF(H27=0,"...",H27*(1+$H$2)/G27*D27) -> ... | J27: =IF(H27=0,"...",I27*E27) -> ... | K27: =IF(A27=0,"...",TODAY()) -> ... | L27: =IFERROR(__xludf.DUMMYFUNCTION("IF(A27=0, ""..."", (GOOGLEFINANCE(A27)*(1-$H$2) ))"),"...") -> ... | N27: =IF(A27=0,"...",(L27)*E27+M27) -> ... | O27: =IF(H27=0,"...",(K27-F27)) -> ... | P27: =IF(H27=0,"...",N27/J27-1) -> ... | Q27: =IF(H27=0,"...",N27-J27) -> ... | R27: =IF(H27=0,"...",N27/$N$28) -> ...
A28: TOTAL | J28: =IF(SUM(J$4:J27)=0,"...",SUM(J$4:J27)) -> 235.91095 | M28: =IF(J28="...","...",SUM(M$4:M27)) -> 0 | N28: =IF(J28="...","...",SUM(N$4:N27)) -> #DIV/0! | P28: =IF(J28="...","...",N28/J28-1) -> #DIV/0! | Q28: =IF(J28="...","...",SUM(Q$4:Q27)) -> 64.402789 | R28: =IF(J28="...","...",N28/N28) -> #DIV/0!
A31: OPERACIONES CERRADAS
A33: Ticker | B33: Broker | C33: Cantidad | D33: Ratio | E33: Cantidad (Real) | F33: Fecha compra | G33: Dólar compra | H33: Precio compra | I33: Precio (USD) | J33: Valor compra | K33: Fecha cierre | L33: Precio cierre (USD) | M33: Dividendos | N33: Valor actual | O33: Días | P33: Variación (%) | Q33: Variación ($)
A57: TOTAL | J57: =IF(SUM(J$34:J56)=0,"...",SUM(J$34:J56)) -> ... | N57: =IF(J57="...","...",SUM(N$34:N56)) -> ... | P57: =IF(J57="...","...",N57/J57-1) -> ... | Q57: =IF(J57="...","...",SUM(Q$34:Q56)) -> ...

Sheet Info CEDEARs
A1: Ticker US | B1: Ticker AR | C1: Precio USD | D1: Precio ARS | E1: Ratio | F1: Dolar CCL | G1: Diferencia Promedio($) | H1: Diferencia Promedio(%) | J1: Dolar CCL Promedio
A2: SPY | B2: SPY | C2: =IFERROR(__xludf.DUMMYFUNCTION("IFERROR(googlefinance(A2),""No Disponible"")"),662.29) -> 662.29 | D2: =iferror(vlookup(A2,'Info Pesos'!$A$1:N453,2,0),"No Disponible") -> 15.25 | E2: 20 | F2: =IF(C2=0, "...", IF(C2="No Disponible", "No Disponible", IF(D2="No Disponible", "No Disponible", IF(A2=0, "...", D2/C2*E2)))) -> 0.46052334 | G2: =IFERROR(F2-$J$3,"No Disponible") -> -1471.7881 | H2: =IFERROR(IF(A2= 0,"...",(F2-$J$3)/$J$3),"No Disponible") -> -0.9996872
A3: QQQ | B3: QQQ | C3: =IFERROR(__xludf.DUMMYFUNCTION("IFERROR(googlefinance(A3),""No Disponible"")"),593.72) -> 593.72 | D3: =iferror(vlookup(A3,'Info Pesos'!$A$1:N454,2,0),"No Disponible") -> 23,730.00 | E3: 20 | F3: =IF(C3=0, "...", IF(C3="No Disponible", "No Disponible", IF(D3="No Disponible", "No Disponible", IF(A3=0, "...", D3/C3*E3)))) -> 799.3667 | G3: =IFERROR(F3-$J$3,"No Disponible") -> -672.88192 | H3: =IFERROR(IF(A3= 0,"...",(F3-$J$3)/$J$3),"No Disponible") -> -0.45704367 | J3: =(F21+F112+F170+F172+F171)/5 -> 1472.2486
A4: DIA | B4: DIA | C4: =IFERROR(__xludf.DUMMYFUNCTION("IFERROR(googlefinance(A4),""No Disponible"")"),466.41) -> 466.41 | D4: =iferror(vlookup(A4,'Info Pesos'!$A$1:N455,2,0),"No Disponible") -> 11,270.00 | E4: 20 | F4: =IF(C4=0, "...", IF(C4="No Disponible", "No Disponible", IF(D4="No Disponible", "No Disponible", IF(A4=0, "...", D4/C4*E4)))) -> 483.2658 | G4: =IFERROR(F4-$J$3,"No Disponible") -> -988.98283 | H4: =IFERROR(IF(A4= 0,"...",(F4-$J$3)/$J$3),"No Disponible") -> -0.67174987
A5: IWM | B5: IWM | C5: =IFERROR(__xludf.DUMMYFUNCTION("IFERROR(googlefinance(A5),""No Disponible"")"),246.59) -> 246.59 | D5: =iferror(vlookup(A5,'Info Pesos'!$A$1:N456,2,0),"No Disponible") -> 8,405.00 | E5: 10 | F5: =IF(C5=0, "...", IF(C5="No Disponible", "No Disponible", IF(D5="No Disponible", "No Disponible", IF(A5=0, "...", D5/C5*E5)))) -> 340.84918 | G5: =IFERROR(F5-$J$3,"No Disponible") -> -1131.3994 | H5: =IFERROR(IF(A5= 0,"...",(F5-$J$3)/$J$3),"No Disponible") -> -0.76848395
A6: EEM | B6: EEM | C6: =IFERROR(__xludf.DUMMYFUNCTION("IFERROR(googlefinance(A6),""No Disponible"")"),56.8) -> 56.8 | D6: =iferror(vlookup(A6,'Info Pesos'!$A$1:N457,2,0),"No Disponible") -> 36.86 | E6: 5 | F6: =IF(C6=0, "...", IF(C6="No Disponible", "No Disponible", IF(D6="No Disponible", "No Disponible", IF(A6=0, "...", D6/C6*E6)))) -> 3.2447183 | G6: =IFERROR(F6-$J$3,"No Disponible") -> -1469.0039 | H6: =IFERROR(IF(A6= 0,"...",(F6-$J$3)/$J$3),"No Disponible") -> -0.99779608
A7: XLF | B7: XLF | C7: =IFERROR(__xludf.DUMMYFUNCTION("IFERROR(googlefinance(A7),""No Disponible"")"),48.89) -> 48.89 | D7: =iferror(vlookup(A7,'Info Pesos'!$A$1:N458,2,0),"No Disponible") -> 39.21 | E7: 2 | F7: =IF(C7=0, "...", IF(C7="No Disponible", "No Disponible", IF(D7="No Disponible", "No Disponible", IF(A7=0, "...", D7/C7*E7)))) -> 1.604009 | G7: =IFERROR(F7-$J$3,"No Disponible") -> -1470.6446 | H7: =IFERROR(IF(A7= 0,"...",(F7-$J$3)/$J$3),"No Disponible") -> -0.9989105
A8: XLE | B8: XLE | C8: =IFERROR(__xludf.DUMMYFUNCTION("IFERROR(googlefinance(A8),""No Disponible"")"),57.7) -> 57.7 | D8: =iferror(vlookup(A8,'Info Pesos'!$A$1:N459,2,0),"No Disponible") -> 7.76 | E8: 2 | F8: =IF(C8=0, "...", IF(C8="No Disponible", "No Disponible", IF(D8="No Disponible", "No Disponible", IF(A8=0, "...", D8/C8*E8)))) -> 0.26897747 | G8: =IFERROR(F8-$J$3,"No Disponible") -> -1471.9796 | H8: =IFERROR(IF(A8= 0,"...",(F8-$J$3)/$J$3),"No Disponible") -> -0.9998173
A9: EWZ | B9: EWZ | C9: =IFERROR(__xludf.DUMMYFUNCTION("IFERROR(googlefinance(A9),""No Disponible"")"),35.49) -> 35.49 | D9: =iferror(vlookup(A9,'Info Pesos'!$A$1:N460,2,0),"No Disponible") -> 8.51 | E9: 2 | F9: =IF(C9=0, "...", IF(C9="No Disponible", "No Disponible", IF(D9="No Disponible", "No Disponible", IF(A9=0, "...", D9/C9*E9)))) -> 0.47957171 | G9: =IFERROR(F9-$J$3,"No Disponible") -> -1471.7691 | H9: =IFERROR(IF(A9= 0,"...",(F9-$J$3)/$J$3),"No Disponible") -> -0.99967426
A10: ARKK | B10: ARKK | C10: =IFERROR(__xludf.DUMMYFUNCTION("IFERROR(googlefinance(A10),""No Disponible"")"),7.44) -> 7.44 | D10: =iferror(vlookup(A10,'Info Pesos'!$A$1:N461,2,0),"No Disponible") -> 2,602.50 | E10: 10 | F10: =IF(C10=0, "...", IF(C10="No Disponible", "No Disponible", IF(D10="No Disponible", "No Disponible", IF(A10=0, "...", D10/C10*E10)))) -> 3497.9839 | G10: =IFERROR(F10-$J$3,"No Disponible") -> 2025.7352 | H10: =IFERROR(IF(A10= 0,"...",(F10-$J$3)/$J$3),"No Disponible") -> 1.3759464
A11: ABT | B11: ABT | C11: =IFERROR(__xludf.DUMMYFUNCTION("IFERROR(googlefinance(A11),""No Disponible"")"),108.03) -> 108.03 | D11: =iferror(vlookup(A11,'Info Pesos'!$A$1:N462,2,0),"No Disponible") -> 39,580.00 | E11: 4 | F11: =IF(C11=0, "...", IF(C11="No Disponible", "No Disponible", IF(D11="No Disponible", "No Disponible", IF(A11=0, "...", D11/C11*E11)))) -> 1465.5188 | G11: =IFERROR(F11-$J$3,"No Disponible") -> -6.7297857 | H11: =IFERROR(IF(A11= 0,"...",(F11-$J$3)/$J$3),"No Disponible") -> -0.0045710932
A12: HWM | B12: HWM | C12: =IFERROR(__xludf.DUMMYFUNCTION("IFERROR(googlefinance(A12),""No Disponible"")"),236.75) -> 236.75 | D12: =iferror(vlookup(A12,'Info Pesos'!$A$1:N463,2,0),"No Disponible") -> 348,450.00 | E12: 1 | F12: =IF(C12=0, "...", IF(C12="No Disponible", "No Disponible", IF(D12="No Disponible", "No Disponible", IF(A12=0, "...", D12/C12*E12)))) -> 1471.8057 | G12: =IFERROR(F12-$J$3,"No Disponible") -> -0.44292086 | H12: =IFERROR(IF(A12= 0,"...",(F12-$J$3)/$J$3),"No Disponible") -> -0.00030084651
A13: AEG | B13: AEG | C13: =IFERROR(__xludf.DUMMYFUNCTION("IFERROR(googlefinance(A13),""No Disponible"")"),6.79) -> 6.79 | D13: =iferror(vlookup(A13,'Info Pesos'!$A$1:N464,2,0),"No Disponible") -> 10,020.00 | E13: 1 | F13: =IF(C13=0, "...", IF(C13="No Disponible", "No Disponible", IF(D13="No Disponible", "No Disponible", IF(A13=0, "...", D13/C13*E13)))) -> 1475.6996 | G13: =IFERROR(F13-$J$3,"No Disponible") -> 3.4509351 | H13: =IFERROR(IF(A13= 0,"...",(F13-$J$3)/$J$3),"No Disponible") -> 0.0023439893
A14: MO | B14: MO | C14: =IFERROR(__xludf.DUMMYFUNCTION("IFERROR(googlefinance(A14),""No Disponible"")"),67.89) -> 67.89 | D14: =iferror(vlookup(A14,'Info Pesos'!$A$1:N465,2,0),"No Disponible") -> 25,080.00 | E14: 4 | F14: =IF(C14=0, "...", IF(C14="No Disponible", "No Disponible", IF(D14="No Disponible", "No Disponible", IF(A14=0, "...", D14/C14*E14)))) -> 1477.6845 | G14: =IFERROR(F14-$J$3,"No Disponible") -> 5.4358665 | H14: =IFERROR(IF(A14= 0,"...",(F14-$J$3)/$J$3),"No Disponible") -> 0.0036922205
A15: AEM | B15: AEM | C15: =IFERROR(__xludf.DUMMYFUNCTION("IFERROR(googlefinance(A15),""No Disponible"")"),207.54) -> 207.54 | D15: =iferror(vlookup(A15,'Info Pesos'!$A$1:N466,2,0),"No Disponible") -> 50,850.00 | E15: 6 | F15: =IF(C15=0, "...", IF(C15="No Disponible", "No Disponible", IF(D15="No Disponible", "No Disponible", IF(A15=0, "...", D15/C15*E15)))) -> 1470.0781 | G15: =IFERROR(F15-$J$3,"No Disponible") -> -2.1705658 | H15: =IFERROR(IF(A15= 0,"...",(F15-$J$3)/$J$3),"No Disponible") -> -0.0014743202
A16: AMX | B16: AMX | C16: =IFERROR(__xludf.DUMMYFUNCTION("IFERROR(googlefinance(A16),""No Disponible"")"),22.99) -> 22.99 | D16: =iferror(vlookup(A16,'Info Pesos'!$A$1:N467,2,0),"No Disponible") -> 33,680.00 | E16: 1 | F16: =IF(C16=0, "...", IF(C16="No Disponible", "No Disponible", IF(D16="No Disponible", "No Disponible", IF(A16=0, "...", D16/C16*E16)))) -> 1464.9848 | G16: =IFERROR(F16-$J$3,"No Disponible") -> -7.2638471 | H16: =IFERROR(IF(A16= 0,"...",(F16-$J$3)/$J$3),"No Disponible") -> -0.0049338454
A17: AXP | B17: AXP | C17: =IFERROR(__xludf.DUMMYFUNCTION("IFERROR(googlefinance(A17),""No Disponible"")"),299.96) -> 299.96 | D17: =iferror(vlookup(A17,'Info Pesos'!$A$1:N468,2,0),"No Disponible") -> 29,360.00 | E17: 15 | F17: =IF(C17=0, "...", IF(C17="No Disponible", "No Disponible", IF(D17="No Disponible", "No Disponible", IF(A17=0, "...", D17/C17*E17)))) -> 1468.1958 | G17: =IFERROR(F17-$J$3,"No Disponible") -> -4.0528636 | H17: =IFERROR(IF(A17= 0,"...",(F17-$J$3)/$J$3),"No Disponible") -> -0.0027528391
A18: AIG | B18: AIG | C18: =IFERROR(__xludf.DUMMYFUNCTION("IFERROR(googlefinance(A18),""No Disponible"")"),76.74) -> 76.74 | D18: =iferror(vlookup(A18,'Info Pesos'!$A$1:N469,2,0),"No Disponible") -> No Disponible | E18: 5 | F18: =IF(C18=0, "...", IF(C18="No Disponible", "No Disponible", IF(D18="No Disponible", "No Disponible", IF(A18=0, "...", D18/C18*E18)))) -> No Disponible | G18: =IFERROR(F18-$J$3,"No Disponible") -> No Disponible | H18: =IFERROR(IF(A18= 0,"...",(F18-$J$3)/$J$3),"No Disponible") -> No Disponible
A19: AMGN | B19: AMGN | C19: =IFERROR(__xludf.DUMMYFUNCTION("IFERROR(googlefinance(A19),""No Disponible"")"),366.21) -> 366.21 | D19: =iferror(vlookup(A19,'Info Pesos'!$A$1:N470,2,0),"No Disponible") -> 17,990.00 | E19: 30 | F19: =IF(C19=0, "...", IF(C19="No Disponible", "No Disponible", IF(D19="No Disponible", "No Disponible", IF(A19=0, "...", D19/C19*E19)))) -> 1473.7446 | G19: =IFERROR(F19-$J$3,"No Disponible") -> 1.4959497 | H19: =IFERROR(IF(A19= 0,"...",(F19-$J$3)/$J$3),"No Disponible") -> 0.0010160986
A20: ADI | B20: ADI | C20: =IFERROR(__xludf.DUMMYFUNCTION("IFERROR(googlefinance(A20),""No Disponible"")"),306.07) -> 306.07 | D20: =iferror(vlookup(A20,'Info Pesos'!$A$1:N471,2,0),"No Disponible") -> 29,880.00 | E20: 15 | F20: =IF(C20=0, "...", IF(C20="No Disponible", "No Disponible", IF(D20="No Disponible", "No Disponible", IF(A20=0, "...", D20/C20*E20)))) -> 1464.3709 | G20: =IFERROR(F20-$J$3,"No Disponible") -> -7.8777275 | H20: =IFERROR(IF(A20= 0,"...",(F20-$J$3)/$J$3),"No Disponible") -> -0.0053508133
A21: AAPL | B21: AAPL | C21: =IFERROR(__xludf.DUMMYFUNCTION("IFERROR(googlefinance(A21),""No Disponible"")"),250.12) -> 250.12 | D21: =iferror(vlookup(A21,'Info Pesos'!$A$1:N472,2,0),"No Disponible") -> 18,410.00 | E21: 20 | F21: =IF(C21=0, "...", IF(C21="No Disponible", "No Disponible", IF(D21="No Disponible", "No Disponible", IF(A21=0, "...", D21/C21*E21)))) -> 1472.0934 | G21: =IFERROR(F21-$J$3,"No Disponible") -> -0.15522791 | H21: =IFERROR(IF(A21= 0,"...",(F21-$J$3)/$J$3),"No Disponible") -> -0.00010543593
A22: AMAT | B22: AMAT | C22: =IFERROR(__xludf.DUMMYFUNCTION("IFERROR(googlefinance(A22),""No Disponible"")"),341.53) -> 341.53 | D22: =iferror(vlookup(A22,'Info Pesos'!$A$1:N473,2,0),"No Disponible") -> 100,300.00 | E22: 5 | F22: =IF(C22=0, "...", IF(C22="No Disponible", "No Disponible", IF(D22="No Disponible", "No Disponible", IF(A22=0, "...", D22/C22*E22)))) -> 1468.3922 | G22: =IFERROR(F22-$J$3,"No Disponible") -> -3.8563881 | H22: =IFERROR(IF(A22= 0,"...",(F22-$J$3)/$J$3),"No Disponible") -> -0.0026193865
A23: T | B23: T | C23: =IFERROR(__xludf.DUMMYFUNCTION("IFERROR(googlefinance(A23),""No Disponible"")"),27.72) -> 27.72 | D23: =iferror(vlookup(A23,'Info Pesos'!$A$1:N474,2,0),"No Disponible") -> No Disponible | E23: 3 | F23: =IF(C23=0, "...", IF(C23="No Disponible", "No Disponible", IF(D23="No Disponible", "No Disponible", IF(A23=0, "...", D23/C23*E23)))) -> No Disponible | G23: =IFERROR(F23-$J$3,"No Disponible") -> No Disponible | H23: =IFERROR(IF(A23= 0,"...",(F23-$J$3)/$J$3),"No Disponible") -> No Disponible
A24: ADP | B24: ADP | C24: =IFERROR(__xludf.DUMMYFUNCTION("IFERROR(googlefinance(A24),""No Disponible"")"),208.52) -> 208.52 | D24: =iferror(vlookup(A24,'Info Pesos'!$A$1:N475,2,0),"No Disponible") -> 51,225.00 | E24: 6 | F24: =IF(C24=0, "...", IF(C24="No Disponible", "No Disponible", IF(D24="No Disponible", "No Disponible", IF(A24=0, "...", D24/C24*E24)))) -> 1473.9593 | G24: =IFERROR(F24-$J$3,"No Disponible") -> 1.7107094 | H24: =IFERROR(IF(A24= 0,"...",(F24-$J$3)/$J$3),"No Disponible") -> 0.0011619704
A25: AVY | B25: AVY | C25: =IFERROR(__xludf.DUMMYFUNCTION("IFERROR(googlefinance(A25),""No Disponible"")"),170.77) -> 170.77 | D25: =iferror(vlookup(A25,'Info Pesos'!$A$1:N476,2,0),"No Disponible") -> 13,980.00 | E25: 18 | F25: =IF(C25=0, "...", IF(C25="No Disponible", "No Disponible", IF(D25="No Disponible", "No Disponible", IF(A25=0, "...", D25/C25*E25)))) -> 1473.5609 | G25: =IFERROR(F25-$J$3,"No Disponible") -> 1.3123068 | H25: =IFERROR(IF(A25= 0,"...",(F25-$J$3)/$J$3),"No Disponible") -> 0.00089136224
A26: CAR | B26: CAR | C26: =IFERROR(__xludf.DUMMYFUNCTION("IFERROR(googlefinance(A26),""No Disponible"")"),100.71) -> 100.71 | D26: =iferror(vlookup(A26,'Info Pesos'!$A$1:N477,2,0),"No Disponible") -> 5,665.00 | E26: 26 | F26: =IF(C26=0, "...", IF(C26="No Disponible", "No Disponible", IF(D26="No Disponible", "No Disponible", IF(A26=0, "...", D26/C26*E26)))) -> 1462.5161 | G26: =IFERROR(F26-$J$3,"No Disponible") -> -9.7324876 | H26: =IFERROR(IF(A26= 0,"...",(F26-$J$3)/$J$3),"No Disponible") -> -0.0066106278
A27: AZN | B27: AZN | C27: =IFERROR(__xludf.DUMMYFUNCTION("IFERROR(googlefinance(A27),""No Disponible"")"),189.9) -> 189.9 | D27: =iferror(vlookup(A27,'Info Pesos'!$A$1:N478,2,0),"No Disponible") -> 70,025.00 | E27: 2 | F27: =IF(C27=0, "...", IF(C27="No Disponible", "No Disponible", IF(D27="No Disponible", "No Disponible", IF(A27=0, "...", D27/C27*E27)))) -> 737.49342 | G27: =IFERROR(F27-$J$3,"No Disponible") -> -734.75521 | H27: =IFERROR(IF(A27= 0,"...",(F27-$J$3)/$J$3),"No Disponible") -> -0.49907006
A28: BBVA | B28: BBVA | C28: =IFERROR(__xludf.DUMMYFUNCTION("IFERROR(googlefinance(A28),""No Disponible"")"),20.45) -> 20.45 | D28: =iferror(vlookup(A28,'Info Pesos'!$A$1:N479,2,0),"No Disponible") -> No Disponible | E28: 1 | F28: =IF(C28=0, "...", IF(C28="No Disponible", "No Disponible", IF(D28="No Disponible", "No Disponible", IF(A28=0, "...", D28/C28*E28)))) -> No Disponible | G28: =IFERROR(F28-$J$3,"No Disponible") -> No Disponible | H28: =IFERROR(IF(A28= 0,"...",(F28-$J$3)/$J$3),"No Disponible") -> No Disponible
A29: BBD | B29: BBD | C29: =IFERROR(__xludf.DUMMYFUNCTION("IFERROR(googlefinance(A29),""No Disponible"")"),3.53) -> 3.53 | D29: =iferror(vlookup(A29,'Info Pesos'!$A$1:N480,2,0),"No Disponible") -> 5,200.00 | E29: 1 | F29: =IF(C29=0, "...", IF(C29="No Disponible", "No Disponible", IF(D29="No Disponible", "No Disponible", IF(A29=0, "...", D29/C29*E29)))) -> 1473.0878 | G29: =IFERROR(F29-$J$3,"No Disponible") -> 0.83919562 | H29: =IFERROR(IF(A29= 0,"...",(F29-$J$3)/$J$3),"No Disponible") -> 0.00057000944
A30: BSBR | B30: BSBR | C30: =IFERROR(__xludf.DUMMYFUNCTION("IFERROR(googlefinance(A30),""No Disponible"")"),5.72) -> 5.72 | D30: =iferror(vlookup(A30,'Info Pesos'!$A$1:N481,2,0),"No Disponible") -> 8,480.00 | E30: 1 | F30: =IF(C30=0, "...", IF(C30="No Disponible", "No Disponible", IF(D30="No Disponible", "No Disponible", IF(A30=0, "...", D30/C30*E30)))) -> 1482.5175 | G30: =IFERROR(F30-$J$3,"No Disponible") -> 10.268859 | H30: =IFERROR(IF(A30= 0,"...",(F30-$J$3)/$J$3),"No Disponible") -> 0.0069749493
A31: BAC | B31: BAC | C31: =IFERROR(__xludf.DUMMYFUNCTION("IFERROR(googlefinance(A31),""No Disponible"")"),46.72) -> 46.72 | D31: =iferror(vlookup(A31,'Info Pesos'!$A$1:N482,2,0),"No Disponible") -> No Disponible | E31: 4 | F31: =IF(C31=0, "...", IF(C31="No Disponible", "No Disponible", IF(D31="No Disponible", "No Disponible", IF(A31=0, "...", D31/C31*E31)))) -> No Disponible | G31: =IFERROR(F31-$J$3,"No Disponible") -> No Disponible | H31: =IFERROR(IF(A31= 0,"...",(F31-$J$3)/$J$3),"No Disponible") -> No Disponible
A32: BCS | B32: BCS | C32: =IFERROR(__xludf.DUMMYFUNCTION("IFERROR(googlefinance(A32),""No Disponible"")"),20.47) -> 20.47 | D32: =iferror(vlookup(A32,'Info Pesos'!$A$1:N483,2,0),"No Disponible") -> 30,080.00 | E32: 1 | F32: =IF(C32=0, "...", IF(C32="No Disponible", "No Disponible", IF(D32="No Disponible", "No Disponible", IF(A32=0, "...", D32/C32*E32)))) -> 1469.4675 | G32: =IFERROR(F32-$J$3,"No Disponible") -> -2.7811096 | H32: =IFERROR(IF(A32= 0,"...",(F32-$J$3)/$J$3),"No Disponible") -> -0.0018890217
A33: GOLD | B33: GOLD | C33: =IFERROR(__xludf.DUMMYFUNCTION("IFERROR(googlefinance(A33),""No Disponible"")"),47.47) -> 47.47 | D33: =iferror(vlookup(A33,'Info Pesos'!$A$1:N484,2,0),"No Disponible") -> No Disponible | E33: 2 | F33: =IF(C33=0, "...", IF(C33="No Disponible", "No Disponible", IF(D33="No Disponible", "No Disponible", IF(A33=0, "...", D33/C33*E33)))) -> No Disponible | G33: =IFERROR(F33-$J$3,"No Disponible") -> No Disponible | H33: =IFERROR(IF(A33= 0,"...",(F33-$J$3)/$J$3),"No Disponible") -> No Disponible
A34: BAS GR | B34: BAS GR | C34: =IFERROR(__xludf.DUMMYFUNCTION("IFERROR(googlefinance(A34),""No Disponible"")"),"No Disponible") -> No Disponible | D34: =iferror(vlookup(A34,'Info Pesos'!$A$1:N485,2,0),"No Disponible") -> No Disponible | E34: 2 | F34: =IF(C34=0, "...", IF(C34="No Disponible", "No Disponible", IF(D34="No Disponible", "No Disponible", IF(A34=0, "...", D34/C34*E34)))) -> No Disponible | G34: =IFERROR(F34-$J$3,"No Disponible") -> No Disponible | H34: =IFERROR(IF(A34= 0,"...",(F34-$J$3)/$J$3),"No Disponible") -> No Disponible
A35: BAYN GR | B35: BAYN GR | C35: =IFERROR(__xludf.DUMMYFUNCTION("IFERROR(googlefinance(A35),""No Disponible"")"),"No Disponible") -> No Disponible | D35: =iferror(vlookup(A35,'Info Pesos'!$A$1:N486,2,0),"No Disponible") -> No Disponible | E35: 3 | F35: =IF(C35=0, "...", IF(C35="No Disponible", "No Disponible", IF(D35="No Disponible", "No Disponible", IF(A35=0, "...", D35/C35*E35)))) -> No Disponible | G35: =IFERROR(F35-$J$3,"No Disponible") -> No Disponible | H35: =IFERROR(IF(A35= 0,"...",(F35-$J$3)/$J$3),"No Disponible") -> No Disponible
A36: BHP | B36: BHP | C36: =IFERROR(__xludf.DUMMYFUNCTION("IFERROR(googlefinance(A36),""No Disponible"")"),68.74) -> 68.74 | D36: =iferror(vlookup(A36,'Info Pesos'!$A$1:N487,2,0),"No Disponible") -> 50,600.00 | E36: 2 | F36: =IF(C36=0, "...", IF(C36="No Disponible", "No Disponible", IF(D36="No Disponible", "No Disponible", IF(A36=0, "...", D36/C36*E36)))) -> 1472.2141 | G36: =IFERROR(F36-$J$3,"No Disponible") -> -0.034482842 | H36: =IFERROR(IF(A36= 0,"...",(F36-$J$3)/$J$3),"No Disponible") -> -2.3421887e-05
A37: BA | B37: BA | C37: =IFERROR(__xludf.DUMMYFUNCTION("IFERROR(googlefinance(A37),""No Disponible"")"),209.89) -> 209.89 | D37: =iferror(vlookup(A37,'Info Pesos'!$A$1:N488,2,0),"No Disponible") -> 12,830.00 | E37: 24 | F37: =IF(C37=0, "...", IF(C37="No Disponible", "No Disponible", IF(D37="No Disponible", "No Disponible", IF(A37=0, "...", D37/C37*E37)))) -> 1467.0542 | G37: =IFERROR(F37-$J$3,"No Disponible") -> -5.1944518 | H37: =IFERROR(IF(A37= 0,"...",(F37-$J$3)/$J$3),"No Disponible") -> -0.0035282436
A38: BP | B38: BP | C38: =IFERROR(__xludf.DUMMYFUNCTION("IFERROR(googlefinance(A38),""No Disponible"")"),42.67) -> 42.67 | D38: =iferror(vlookup(A38,'Info Pesos'!$A$1:N489,2,0),"No Disponible") -> 12,500.00 | E38: 5 | F38: =IF(C38=0, "...", IF(C38="No Disponible", "No Disponible", IF(D38="No Disponible", "No Disponible", IF(A38=0, "...", D38/C38*E38)))) -> 1464.7293 | G38: =IFERROR(F38-$J$3,"No Disponible") -> -7.5193051 | H38: =IFERROR(IF(A38= 0,"...",(F38-$J$3)/$J$3),"No Disponible") -> -0.0051073609
A39: BMY | B39: BMY | C39: =IFERROR(__xludf.DUMMYFUNCTION("IFERROR(googlefinance(A39),""No Disponible"")"),59.08) -> 59.08 | D39: =iferror(vlookup(A39,'Info Pesos'!$A$1:N490,2,0),"No Disponible") -> No Disponible | E39: 3 | F39: =IF(C39=0, "...", IF(C39="No Disponible", "No Disponible", IF(D39="No Disponible", "No Disponible", IF(A39=0, "...", D39/C39*E39)))) -> No Disponible | G39: =IFERROR(F39-$J$3,"No Disponible") -> No Disponible | H39: =IFERROR(IF(A39= 0,"...",(F39-$J$3)/$J$3),"No Disponible") -> No Disponible
A40: BG | B40: BG | C40: =IFERROR(__xludf.DUMMYFUNCTION("IFERROR(googlefinance(A40),""No Disponible"")"),124.73) -> 124.73 | D40: =iferror(vlookup(A40,'Info Pesos'!$A$1:N491,2,0),"No Disponible") -> No Disponible | E40: 5 | F40: =IF(C40=0, "...", IF(C40="No Disponible", "No Disponible", IF(D40="No Disponible", "No Disponible", IF(A40=0, "...", D40/C40*E40)))) -> No Disponible | G40: =IFERROR(F40-$J$3,"No Disponible") -> No Disponible | H40: =IFERROR(IF(A40= 0,"...",(F40-$J$3)/$J$3),"No Disponible") -> No Disponible
...

Sheet Info Pesos
A1: Ticker | C1: =IFERROR(__xludf.DUMMYFUNCTION("IMPORTHTML(""https://iol.invertironline.com/mercado/cotizaciones/argentina/cedears/todos"",""TABLE"",1)"),"Símbolo") -> Símbolo | D1: =IFERROR(__xludf.DUMMYFUNCTION("""COMPUTED_VALUE"""),"Último Operado") -> Último Operado | E1: =IFERROR(__xludf.DUMMYFUNCTION("""COMPUTED_VALUE"""),"Variación Diaria") -> Variación Diaria | F1: =IFERROR(__xludf.DUMMYFUNCTION("""COMPUTED_VALUE"""),"Cantidad Compra") -> Cantidad Compra | G1: =IFERROR(__xludf.DUMMYFUNCTION("""COMPUTED_VALUE"""),"Precio Compra") -> Precio Compra | H1: =IFERROR(__xludf.DUMMYFUNCTION("""COMPUTED_VALUE"""),"Precio Venta") -> Precio Venta | I1: =IFERROR(__xludf.DUMMYFUNCTION("""COMPUTED_VALUE"""),"Cantidad Venta") -> Cantidad Venta | J1: =IFERROR(__xludf.DUMMYFUNCTION("""COMPUTED_VALUE"""),"Apertura") -> Apertura | K1: =IFERROR(__xludf.DUMMYFUNCTION("""COMPUTED_VALUE"""),"Mínimo") -> Mínimo | L1: =IFERROR(__xludf.DUMMYFUNCTION("""COMPUTED_VALUE"""),"Máximo") -> Máximo | M1: =IFERROR(__xludf.DUMMYFUNCTION("""COMPUTED_VALUE"""),"Último Cierre") -> Último Cierre | N1: =IFERROR(__xludf.DUMMYFUNCTION("""COMPUTED_VALUE"""),"Monto Operado") -> Monto Operado
A2: =MID(C2, FIND("* ", C2) + 2, FIND(" *", C2, FIND("* ", C2) + 2) - FIND("* ", C2) - 2) -> AAL | B2: =SUBSTITUTE(SUBSTITUTE(SUBSTITUTE(D2, ".", "\\"), ",", "."), "\\", ",") -> 7,600.00 | C2: =IFERROR(__xludf.DUMMYFUNCTION("""COMPUTED_VALUE"""),"* AAL * Cedear American...") -> * AAL * Cedear American... | D2: =IFERROR(__xludf.DUMMYFUNCTION("""COMPUTED_VALUE"""),"7.600,00") -> 7.600,00 | E2: =IFERROR(__xludf.DUMMYFUNCTION("""COMPUTED_VALUE"""),"-1,29%") -> -1,29% | F2: =IFERROR(__xludf.DUMMYFUNCTION("""COMPUTED_VALUE"""),"-") -> - | G2: =IFERROR(__xludf.DUMMYFUNCTION("""COMPUTED_VALUE"""),"-") -> - | H2: =IFERROR(__xludf.DUMMYFUNCTION("""COMPUTED_VALUE"""),"-") -> - | I2: =IFERROR(__xludf.DUMMYFUNCTION("""COMPUTED_VALUE"""),"-") -> - | J2: =IFERROR(__xludf.DUMMYFUNCTION("""COMPUTED_VALUE"""),"7.690,00") -> 7.690,00 | K2: =IFERROR(__xludf.DUMMYFUNCTION("""COMPUTED_VALUE"""),"7.545,00") -> 7.545,00 | L2: =IFERROR(__xludf.DUMMYFUNCTION("""COMPUTED_VALUE"""),"7.750,00") -> 7.750,00 | M2: =IFERROR(__xludf.DUMMYFUNCTION("""COMPUTED_VALUE"""),"7.600,00") -> 7.600,00 | N2: =IFERROR(__xludf.DUMMYFUNCTION("""COMPUTED_VALUE"""),"180.301.175") -> 180.301.175
A3: =MID(C3, FIND("* ", C3) + 2, FIND(" *", C3, FIND("* ", C3) + 2) - FIND("* ", C3) - 2) -> AALC | B3: =SUBSTITUTE(SUBSTITUTE(SUBSTITUTE(D3, ".", "\\"), ",", "."), "\\", ",") -> 5.38 | C3: =IFERROR(__xludf.DUMMYFUNCTION("""COMPUTED_VALUE"""),"* AALC * Cedear American...") -> * AALC * Cedear American... | D3: =IFERROR(__xludf.DUMMYFUNCTION("""COMPUTED_VALUE"""),"5,38") -> 5,38 | E3: =IFERROR(__xludf.DUMMYFUNCTION("""COMPUTED_VALUE"""),"-3,06%") -> -3,06% | F3: =IFERROR(__xludf.DUMMYFUNCTION("""COMPUTED_VALUE"""),"-") -> - | G3: =IFERROR(__xludf.DUMMYFUNCTION("""COMPUTED_VALUE"""),"-") -> - | H3: =IFERROR(__xludf.DUMMYFUNCTION("""COMPUTED_VALUE"""),"-") -> - | I3: =IFERROR(__xludf.DUMMYFUNCTION("""COMPUTED_VALUE"""),"-") -> - | J3: =IFERROR(__xludf.DUMMYFUNCTION("""COMPUTED_VALUE"""),"5,22") -> 5,22 | K3: =IFERROR(__xludf.DUMMYFUNCTION("""COMPUTED_VALUE"""),"5,22") -> 5,22 | L3: =IFERROR(__xludf.DUMMYFUNCTION("""COMPUTED_VALUE"""),"5,22") -> 5,22 | M3: =IFERROR(__xludf.DUMMYFUNCTION("""COMPUTED_VALUE"""),"5,38") -> 5,38 | N3: =IFERROR(__xludf.DUMMYFUNCTION("""COMPUTED_VALUE"""),47.0) -> 47
A4: =MID(C4, FIND("* ", C4) + 2, FIND(" *", C4, FIND("* ", C4) + 2) - FIND("* ", C4) - 2) -> AALD | B4: =SUBSTITUTE(SUBSTITUTE(SUBSTITUTE(D4, ".", "\\"), ",", "."), "\\", ",") -> 5.29 | C4: =IFERROR(__xludf.DUMMYFUNCTION("""COMPUTED_VALUE"""),"* AALD * Cedear American...") -> * AALD * Cedear American... | D4: =IFERROR(__xludf.DUMMYFUNCTION("""COMPUTED_VALUE"""),"5,29") -> 5,29 | E4: =IFERROR(__xludf.DUMMYFUNCTION("""COMPUTED_VALUE"""),"-3,64%") -> -3,64% | F4: =IFERROR(__xludf.DUMMYFUNCTION("""COMPUTED_VALUE"""),"-") -> - | G4: =IFERROR(__xludf.DUMMYFUNCTION("""COMPUTED_VALUE"""),"-") -> - | H4: =IFERROR(__xludf.DUMMYFUNCTION("""COMPUTED_VALUE"""),"-") -> - | I4: =IFERROR(__xludf.DUMMYFUNCTION("""COMPUTED_VALUE"""),"-") -> - | J4: =IFERROR(__xludf.DUMMYFUNCTION("""COMPUTED_VALUE"""),"5,51") -> 5,51 | K4: =IFERROR(__xludf.DUMMYFUNCTION("""COMPUTED_VALUE"""),"5,31") -> 5,31 | L4: =IFERROR(__xludf.DUMMYFUNCTION("""COMPUTED_VALUE"""),"5,59") -> 5,59 | M4: =IFERROR(__xludf.DUMMYFUNCTION("""COMPUTED_VALUE"""),"5,29") -> 5,29 | N4: =IFERROR(__xludf.DUMMYFUNCTION("""COMPUTED_VALUE"""),13.742) -> 13.742
A5: =MID(C5, FIND("* ", C5) + 2, FIND(" *", C5, FIND("* ", C5) + 2) - FIND("* ", C5) - 2) -> AAP | B5: =SUBSTITUTE(SUBSTITUTE(SUBSTITUTE(D5, ".", "\\"), ",", "."), "\\", ",") -> 5,410.00 | C5: =IFERROR(__xludf.DUMMYFUNCTION("""COMPUTED_VALUE"""),"* AAP * Cedear Advance ...") -> * AAP * Cedear Advance ... | D5: =IFERROR(__xludf.DUMMYFUNCTION("""COMPUTED_VALUE"""),"5.410,00") -> 5.410,00 | E5: =IFERROR(__xludf.DUMMYFUNCTION("""COMPUTED_VALUE"""),"-1,63%") -> -1,63% | F5: =IFERROR(__xludf.DUMMYFUNCTION("""COMPUTED_VALUE"""),"-") -> - | G5: =IFERROR(__xludf.DUMMYFUNCTION("""COMPUTED_VALUE"""),"-") -> - | H5: =IFERROR(__xludf.DUMMYFUNCTION("""COMPUTED_VALUE"""),"-") -> - | I5: =IFERROR(__xludf.DUMMYFUNCTION("""COMPUTED_VALUE"""),"-") -> - | J5: =IFERROR(__xludf.DUMMYFUNCTION("""COMPUTED_VALUE"""),"5.455,00") -> 5.455,00 | K5: =IFERROR(__xludf.DUMMYFUNCTION("""COMPUTED_VALUE"""),"5.275,00") -> 5.275,00 | L5: =IFERROR(__xludf.DUMMYFUNCTION("""COMPUTED_VALUE"""),"5.580,00") -> 5.580,00 | M5: =IFERROR(__xludf.DUMMYFUNCTION("""COMPUTED_VALUE"""),"5.410,00") -> 5.410,00 | N5: =IFERROR(__xludf.DUMMYFUNCTION("""COMPUTED_VALUE"""),"5.998.520") -> 5.998.520
A6: =MID(C6, FIND("* ", C6) + 2, FIND(" *", C6, FIND("* ", C6) + 2) - FIND("* ", C6) - 2) -> AAPL | B6: =SUBSTITUTE(SUBSTITUTE(SUBSTITUTE(D6, ".", "\\"), ",", "."), "\\", ",") -> 18,410.00 | C6: =IFERROR(__xludf.DUMMYFUNCTION("""COMPUTED_VALUE"""),"* AAPL * Cedear Apple Inc.") -> * AAPL * Cedear Apple Inc. | D6: =IFERROR(__xludf.DUMMYFUNCTION("""COMPUTED_VALUE"""),"18.410,00") -> 18.410,00 | E6: =IFERROR(__xludf.DUMMYFUNCTION("""COMPUTED_VALUE"""),"-1,12%") -> -1,12% | F6: =IFERROR(__xludf.DUMMYFUNCTION("""COMPUTED_VALUE"""),"-") -> - | G6: =IFERROR(__xludf.DUMMYFUNCTION("""COMPUTED_VALUE"""),"-") -> - | H6: =IFERROR(__xludf.DUMMYFUNCTION("""COMPUTED_VALUE"""),"-") -> - | I6: =IFERROR(__xludf.DUMMYFUNCTION("""COMPUTED_VALUE"""),"-") -> - | J6: =IFERROR(__xludf.DUMMYFUNCTION("""COMPUTED_VALUE"""),"18.650,00") -> 18.650,00 | K6: =IFERROR(__xludf.DUMMYFUNCTION("""COMPUTED_VALUE"""),"18.300,00") -> 18.300,00 | L6: =IFERROR(__xludf.DUMMYFUNCTION("""COMPUTED_VALUE"""),"18.680,00") -> 18.680,00 | M6: =IFERROR(__xludf.DUMMYFUNCTION("""COMPUTED_VALUE"""),"18.620,00") -> 18.620,00 | N6: =IFERROR(__xludf.DUMMYFUNCTION("""COMPUTED_VALUE"""),"724.994.300") -> 724.994.300
A7: =MID(C7, FIND("* ", C7) + 2, FIND(" *", C7, FIND("* ", C7) + 2) - FIND("* ", C7) - 2) -> AAPLC | B7: =SUBSTITUTE(SUBSTITUTE(SUBSTITUTE(D7, ".", "\\"), ",", "."), "\\", ",") -> 12.58 | C7: =IFERROR(__xludf.DUMMYFUNCTION("""COMPUTED_VALUE"""),"* AAPLC * Cedear Apple Inc.") -> * AAPLC * Cedear Apple Inc. | D7: =IFERROR(__xludf.DUMMYFUNCTION("""COMPUTED_VALUE"""),"12,58") -> 12,58 | E7: =IFERROR(__xludf.DUMMYFUNCTION("""COMPUTED_VALUE"""),"-1,64%") -> -1,64% | F7: =IFERROR(__xludf.DUMMYFUNCTION("""COMPUTED_VALUE"""),"-") -> - | G7: =IFERROR(__xludf.DUMMYFUNCTION("""COMPUTED_VALUE"""),"-") -> - | H7: =IFERROR(__xludf.DUMMYFUNCTION("""COMPUTED_VALUE"""),"-") -> - | I7: =IFERROR(__xludf.DUMMYFUNCTION("""COMPUTED_VALUE"""),"-") -> - | J7: =IFERROR(__xludf.DUMMYFUNCTION("""COMPUTED_VALUE"""),"12,72") -> 12,72 | K7: =IFERROR(__xludf.DUMMYFUNCTION("""COMPUTED_VALUE"""),"12,59") -> 12,59 | L7: =IFERROR(__xludf.DUMMYFUNCTION("""COMPUTED_VALUE"""),"12,72") -> 12,72 | M7: =IFERROR(__xludf.DUMMYFUNCTION("""COMPUTED_VALUE"""),"12,58") -> 12,58 | N7: =IFERROR(__xludf.DUMMYFUNCTION("""COMPUTED_VALUE"""),51.0) -> 51
